Workbook

Sheet 4. DISPENSA E INEXIGIBILIDADE
B3: GESTÃO DE COMPRAS: DISPENSA E INEXIGIBILIDADE | K3: inserir controles de saldos ND | S3: Inserir link gerado no WordPress | AG3: PNCP | AJ3: ARQUIVOS DA LICITAÇÃO (LINKS WORD PRESS - SITE) | AP3: RENOMEAÇÃO AQUIVOS
B4: DATA RECEBIDO | C4: RESPONSÁVEL GCC | D4: STATUS | E4: ETAPA | F4: Nº PROCESSO SIGA | G4: DIRETORIA | H4: ÁREA REQUISITANTE | I4: TIPO DO OBJETO | J4: OBJETO | K4: MODALIDADE | L4: NATUREZA DO CONTRATO | M4: FORNECEDOR | N4: CNPJ/CPF | O4: TIPO DO CONTRATO | P4: NOTA DE EMPENHO | Q4: Nº CONTRATO | R4: Nº CTR assinado | S4: DATA ASSINATURA | T4: INÍCIO VIGÊNCIA | U4: FINAL VIGÊNCIA | V4: VALOR CONTRATO | W4: Nº DEG | X4: FISCAL DO CONTRATO | Y4: SIGILO | Z4: Nº RC SAP | AA4: Nº Fornecedor SAP | AB4: Nº CTR SAP | AC4: DATA FINALIZADO | AD4: DIAS ÚTEIS | AE4: RESPONSÁVEL GESTÃO | AF4: OBSERVAÇÃO | AG4: Nº DA LICITAÇÃO | AH4: Compra divulgada no PNCP | AI4: Publicação do Contrato PNCP | AJ4: Arquivo do contrato | AK4: TR | AL4: JUST. ESCOLHA FORNECEDOR | AM4: ATO RATIFICAÇÃO (Autor. Sup) | AP4: SEQ | AQ4: TR | AR4: JUST. ESCOLHA FORNECEDOR | AS4: ATO RATIFICAÇÃO (Autor. Sup)
B5: 45600 | C5: FRANCIELE | D5: FINALIZADO | E5: FINALIZADO | F5: TLB-PRO-2024/05723 | G5: 2000-DAFRI | H5: GLOG | I5: Serviços | J5: Contratação de empresa especializada em assessoria esportiva, organização, apoio técnico, logístico e estrutural para participação da equipe de colaboradores da Telebras, em caminhada (3km) e corrida (5km e 10km) no evento MARATONA MONUMENTAL DE BRASÍLIA em comemoração ao aniversário de 52 anos da empresa e a Semana Interna de Prevenção de Acidentes do Trabalho (SIPAT. | K5: Dispensa | L5: ADMINISTRATIVO | M5: MARCIA GONCALVES FARIA ROSA | N5: 16.454.959/0001-37 | O5: Nota de Empenho | P5: 2024NE001059 | Q5: 2024NE001059 | R5: 2024NE001059 | S5: 45604 | T5: 45604 | U5: 45657 | V5: 29500 | W5: TLB-DEG-2024/00126 | X5: Rosilda Ferreira da Cunha | Y5: PÚBLICO | Z5: 10015000 | AA5: 10003761 | AB5: 2024NE001059 | AC5: 45600 | AD5: =NETWORKDAYS.INTL(Tab_4.DISP_INEX[[#This Row],[DATA RECEBIDO]],Tab_4.DISP_INEX[[#This Row],[DATA FINALIZADO]],1,Lista!$U$3:$U$15) -> 1 | AJ5: https://www.telebras.com.br/wp-content/uploads/2025/02/69.2024NE001059-MARCIA-GONCALVES-FARIA-ROSA.pdf | AK5: https://www.telebras.com.br/wp-content/uploads/2026/06/1_TR_MARCIA-GONCALVES-FARIA-ROSA.pdf | AL5: https://www.telebras.com.br/wp-content/uploads/2026/06/1_JUST_MARCIA-GONCALVES-FARIA-ROSA.pdf | AM5: - | AP5: 1 | AQ5: =_xlfn.CONCAT(AP5,"_","TR","_",Tab_4.DISP_INEX[[#This Row],[FORNECEDOR]]) -> 1_TR_MARCIA GONCALVES FARIA ROSA | AR5: =_xlfn.CONCAT(AP5,"_","JUST","_",Tab_4.DISP_INEX[[#This Row],[FORNECEDOR]]) -> 1_JUST_MARCIA GONCALVES FARIA ROSA | AS5: =_xlfn.CONCAT(AP5,"_","RAT","_",Tab_4.DISP_INEX[[#This Row],[FORNECEDOR]]) -> 1_RAT_MARCIA GONCALVES FARIA ROSA
B6: 45628 | C6: LUCIANA | D6: FINALIZADO | E6: FINALIZADO | F6: TLB-PRO-2024/04811 | G6: 2000-DAFRI | H6: GPR -ASCOM | I6: Compras | J6: Aquisição de drone | K6: Dispensa | L6: ADMINISTRATIVO | M6: NW SHOP COMÉRCIO LTDA | N6: 30.282.962/0001-41 | O6: Nota de Empenho | P6: 2024NE001121 | Q6: 2024NE001121 | R6: TLB-ASS-2024/17078 | S6: 45632 | T6: 45632 | U6: 45657 | V6: 9495 | W6: TLB-DEG-2024/00137 | X6: Érico Luís Cortes Cazarré | Y6: PÚBLICO | Z6: 10014689 | AB6: 2024NE001121 | AC6: 45646 | AD6: =NETWORKDAYS.INTL(Tab_4.DISP_INEX[[#This Row],[DATA RECEBIDO]],Tab_4.DISP_INEX[[#This Row],[DATA FINALIZADO]],1,Lista!$U$3:$U$15) -> 15 | AJ6: https://www.telebras.com.br/wp-content/uploads/2026/04/1.-2024NE001121-NW-SHOP-COMERCIO-LTDA-1.pdf | AK6: https://www.telebras.com.br/wp-content/uploads/2026/06/2_TR_NW-SHOP-COMERCIO-LTDA.pdf | AL6: https://www.telebras.com.br/wp-content/uploads/2026/06/2_JUST_NW-SHOP-COMERCIO-LTDA.pdf | AM6: - | AP6: 2 | AQ6: =_xlfn.CONCAT(AP6,"_","TR","_",Tab_4.DISP_INEX[[#This Row],[FORNECEDOR]]) -> 2_TR_NW SHOP COMÉRCIO LTDA | AR6: =_xlfn.CONCAT(AP6,"_","JUST","_",Tab_4.DISP_INEX[[#This Row],[FORNECEDOR]]) -> 2_JUST_NW SHOP COMÉRCIO LTDA | AS6: =_xlfn.CONCAT(AP6,"_","RAT","_",Tab_4.DISP_INEX[[#This Row],[FORNECEDOR]]) -> 2_RAT_NW SHOP COMÉRCIO LTDA
B7: 45618 | C7: LUCIANA | D7: FINALIZADO | E7: FINALIZADO | F7: TLB-PRO-2024/03879 | G7: 3000-DTO | H7: GORS | I7: Serviços | J7: Contratação de serviços de reparo e higienização das cadeiras de escritório do CIGR | K7: Dispensa | L7: ADMINISTRATIVO | M7: GS SERVICOS LTDA | N7: 34.292.339/0001-20 | O7: Nota de Empenho | P7: 2024NE001102 | Q7: 2024NE001102 | R7: TLB-ASS-2024/17013 | S7: 45632 | T7: 45632 | U7: 45657 | V7: 4909.98 | W7: TLB-DEG-2024/00148 | X7: Eder Viana Silva | Y7: PÚBLICO | Z7: 10014940 | AB7: - | AD7: =NETWORKDAYS.INTL(Tab_4.DISP_INEX[[#This Row],[DATA RECEBIDO]],Tab_4.DISP_INEX[[#This Row],[DATA FINALIZADO]],1,Lista!$U$3:$U$15) -> -32577 | AJ7: https://www.telebras.com.br/wp-content/uploads/2026/04/2.-2024NE001102-GS-SERVICOS-LTDA-1.pdf | AK7: https://www.telebras.com.br/wp-content/uploads/2026/06/3_TR_GS-SERVICOS-LTDA.pdf | AL7: https://www.telebras.com.br/wp-content/uploads/2026/06/3_JUST_GS-SERVICOS-LTDA.pdf | AM7: - | AP7: 3 | AQ7: =_xlfn.CONCAT(AP7,"_","TR","_",Tab_4.DISP_INEX[[#This Row],[FORNECEDOR]]) -> 3_TR_GS SERVICOS LTDA | AR7: =_xlfn.CONCAT(AP7,"_","JUST","_",Tab_4.DISP_INEX[[#This Row],[FORNECEDOR]]) -> 3_JUST_GS SERVICOS LTDA | AS7: =_xlfn.CONCAT(AP7,"_","RAT","_",Tab_4.DISP_INEX[[#This Row],[FORNECEDOR]]) -> 3_RAT_GS SERVICOS LTDA
B8: 45632 | C8: LUCIANA | D8: FINALIZADO | E8: FINALIZADO | F8: TLB-PRO-2024/06305 | G8: 3000-DTO | H8: GERP | I8: Informática (TIC) | J8: Compra de placas, transceivers e cabos compatíveis com os equipamentos DATACOM para a realização de upgrade do Switch DATACOM 4004 instalado na localidade de Presidente Dutra/MA para atendimento da demanda da Infovia do Maranhão. | K8: Inexigibilidade | L8: ADMINISTRATIVO | M8: Teracom Telemática S.A | N8: 02.820.966/0001-09 | O8: Nota de Empenho | P8: 2024NE001125 | Q8: 2024NE001125 | R8: TLB-ASS-2024/17112 | S8: 45632 | T8: 45632 | U8: 45657 | V8: 56350.5 | W8: TLB-DEG-2024/00149 | X8: MIRELE DE ALMEIDA MENCARI | Y8: PÚBLICO | AB8: - | AC8: =TODAY() -> 46190 | AD8: =NETWORKDAYS.INTL(Tab_4.DISP_INEX[[#This Row],[DATA RECEBIDO]],Tab_4.DISP_INEX[[#This Row],[DATA FINALIZADO]],1,Lista!$U$3:$U$15) -> 398 | AJ8: https://www.telebras.com.br/wp-content/uploads/2026/04/3.-2024NE001125-TERACOM-TELEMATICA-SA-1.pdf | AK8: https://www.telebras.com.br/wp-content/uploads/2026/06/4_TR_Teracom-Telematica-S.A.pdf | AL8: - | AM8: https://www.telebras.com.br/wp-content/uploads/2026/06/4_RAT_Teracom-Telematica-S.A.pdf | AP8: 4 | AQ8: =_xlfn.CONCAT(AP8,"_","TR","_",Tab_4.DISP_INEX[[#This Row],[FORNECEDOR]]) -> 4_TR_Teracom Telemática S.A | AR8: =_xlfn.CONCAT(AP8,"_","JUST","_",Tab_4.DISP_INEX[[#This Row],[FORNECEDOR]]) -> 4_JUST_Teracom Telemática S.A | AS8: =_xlfn.CONCAT(AP8,"_","RAT","_",Tab_4.DISP_INEX[[#This Row],[FORNECEDOR]]) -> 4_RAT_Teracom Telemática S.A
B9: 45342 | C9: FRANCIELE | D9: FINALIZADO | E9: FINALIZADO | F9: TLB-PRO-2024/00927 | G9: 2000-DAFRI | H9: GGP | I9: Serviços | J9: Palestrante moderador para o Evento "Telebras Day" | K9: Inexigibilidade | L9: ADMINISTRATIVO | M9: Inlabs Capacitação Profissional Ltda | N9: 16.700.677/0001-72 | O9: Nota de Empenho | P9: 2024NE000601 | Q9: 2024NE000601 | R9: 2024NE000601 | S9: 45350 | T9: 45350 | U9: 45350 | V9: 32500 | W9: TLB-DEG-2024/00016 | X9: ADRYANA RAMOS DE OLIVEIRA | Y9: PÚBLICO | Z9: 10014463 | AA9: 10004001 | AB9: 2024NE000601 | AC9: 45342 | AD9: =NETWORKDAYS.INTL(Tab_4.DISP_INEX[[#This Row],[DATA RECEBIDO]],Tab_4.DISP_INEX[[#This Row],[DATA FINALIZADO]],1,Lista!$U$3:$U$15) -> 1 | AE9: FRANCIELE | AF9: CAPACITAÇÃO | AJ9: https://www.telebras.com.br/wp-content/uploads/2024/12/14.2024NE000601-INLABS-CAPACITACAO-PROFISSIONAL-LTDA.pdf | AK9: https://www.telebras.com.br/wp-content/uploads/2026/06/5_TR_Inlabs-Capacitacao-Profissional-Ltda.pdf | AL9: https://www.telebras.com.br/wp-content/uploads/2026/06/5_JUST_Inlabs-Capacitacao-Profissional-Ltda.pdf | AM9: https://www.telebras.com.br/wp-content/uploads/2026/06/5_RAT_Inlabs-Capacitacao-Profissional-Ltda.pdf | AP9: 5 | AQ9: =_xlfn.CONCAT(AP9,"_","TR","_",Tab_4.DISP_INEX[[#This Row],[FORNECEDOR]]) -> 5_TR_Inlabs Capacitação Profissional Ltda | AR9: =_xlfn.CONCAT(AP9,"_","JUST","_",Tab_4.DISP_INEX[[#This Row],[FORNECEDOR]]) -> 5_JUST_Inlabs Capacitação Profissional Ltda | AS9: =_xlfn.CONCAT(AP9,"_","RAT","_",Tab_4.DISP_INEX[[#This Row],[FORNECEDOR]]) -> 5_RAT_Inlabs Capacitação Profissional Ltda
B10: 45342 | C10: FRANCIELE | D10: FINALIZADO | E10: FINALIZADO | F10: TLB-PRO-2024/00201 | G10: 2000-DAFRI | H10: GGP | I10: Serviços | J10: Conferência Satellite 2024 | K10: Inexigibilidade | L10: ADMINISTRATIVO | M10: ACCESS INTELLIGENCE, LLC | N10: EX242162 | O10: Nota de Empenho | P10: 2024NE000566 | Q10: 2024NE000566 | R10: 2024NE000566 | S10: 45345 | T10: 45345 | U10: 45345 | V10: 22586.6 | W10: TLB-DEG-2024/00013 | X10: ADRYANA RAMOS DE OLIVEIRA | Y10: PÚBLICO | Z10: 10014468 | AB10: 2024NE000566 | AC10: 45343 | AD10: =NETWORKDAYS.INTL(Tab_4.DISP_INEX[[#This Row],[DATA RECEBIDO]],Tab_4.DISP_INEX[[#This Row],[DATA FINALIZADO]],1,Lista!$U$3:$U$15) -> 2 | AE10: FRANCIELE | AF10: EVENTO | AJ10: https://www.telebras.com.br/wp-content/uploads/2024/12/12.2024NE000566-ACCESS-INTELLIGENCE-LLC.pdf | AK10: https://www.telebras.com.br/wp-content/uploads/2026/06/6_TR_ACCESS-INTELLIGENCE-LLC.pdf | AL10: https://www.telebras.com.br/wp-content/uploads/2026/06/6_JUST_ACCESS-INTELLIGENCE-LLC.pdf | AM10: https://www.telebras.com.br/wp-content/uploads/2026/06/6_RAT_ACCESS-INTELLIGENCE-LLC.pdf | AP10: 6 | AQ10: =_xlfn.CONCAT(AP10,"_","TR","_",Tab_4.DISP_INEX[[#This Row],[FORNECEDOR]]) -> 6_TR_ACCESS INTELLIGENCE, LLC | AR10: =_xlfn.CONCAT(AP10,"_","JUST","_",Tab_4.DISP_INEX[[#This Row],[FORNECEDOR]]) -> 6_JUST_ACCESS INTELLIGENCE, LLC | AS10: =_xlfn.CONCAT(AP10,"_","RAT","_",Tab_4.DISP_INEX[[#This Row],[FORNECEDOR]]) -> 6_RAT_ACCESS INTELLIGENCE, LLC
B11: 45351 | C11: FRANCIELE | D11: FINALIZADO | E11: FINALIZADO | F11: TLB-PRO-2024/00613 | G11: 2000-DAFRI | H11: GIRC | I11: Serviços | J11: Filiação da Telebras à Fundação Nacional da Qualidade – FNQ | K11: Inexigibilidade | L11: ADMINISTRATIVO | M11: Fundação Nacional de Qualidade - FNQ | N11: 67.145.383/0001-67 | O11: Nota de Empenho | P11: 2024NE000891 | Q11: 2024NE000891 | R11: TLB-ASS-2024/10894 | S11: 45488 | T11: 45524 | U11: 45889 | V11: 6615 | W11: TLB-DEG-2024/00098 | X11: JANINE OLIVEIRA | Y11: PÚBLICO | Z11: 10014428 | AA11: 10003997 | AB11: 2024NE000891 | AC11: 45357 | AD11: =NETWORKDAYS.INTL(Tab_4.DISP_INEX[[#This Row],[DATA RECEBIDO]],Tab_4.DISP_INEX[[#This Row],[DATA FINALIZADO]],1,Lista!$U$3:$U$15) -> 5 | AE11: FRANCIELE | AF11: FILIAÇÃO | AJ11: https://www.telebras.com.br/wp-content/uploads/2026/04/12.-2024NE000891-FUNDACAO-NACIONAL-DE-QUALIDADE-FNQ-1.pdf | AK11: https://www.telebras.com.br/wp-content/uploads/2026/06/7_TR_Fundacao-Nacional-de-Qualidade-FNQ.pdf | AL11: https://www.telebras.com.br/wp-content/uploads/2026/06/7_JUST_Fundacao-Nacional-de-Qualidade-FNQ.pdf | AM11: https://www.telebras.com.br/wp-content/uploads/2026/06/7_RAT_Fundacao-Nacional-de-Qualidade-FNQ.pdf | AP11: 7 | AQ11: =_xlfn.CONCAT(AP11,"_","TR","_",Tab_4.DISP_INEX[[#This Row],[FORNECEDOR]]) -> 7_TR_Fundação Nacional de Qualidade - FNQ | AR11: =_xlfn.CONCAT(AP11,"_","JUST","_",Tab_4.DISP_INEX[[#This Row],[FORNECEDOR]]) -> 7_JUST_Fundação Nacional de Qualidade - FNQ | AS11: =_xlfn.CONCAT(AP11,"_","RAT","_",Tab_4.DISP_INEX[[#This Row],[FORNECEDOR]]) -> 7_RAT_Fundação Nacional de Qualidade - FNQ
B12: 45364 | C12: ROSILDA | D12: FINALIZADO | E12: FINALIZADO | F12: TLB-PRO-2024/01201 | G12: 2000-DAFRI | H12: GCC | I12: Serviços | J12: Zênite Fácil - Estatais - Assinatura anual | K12: Inexigibilidade | L12: ADMINISTRATIVO | M12: Zênite Informação e Consultoria S/A | N12: 86.781.069/0001-15 | O12: Nota de Empenho | P12: 2024NE000632 | Q12: 2024NE000632 | R12: TLB-ASS-2024/04794 | S12: 45373 | T12: 45373 | U12: 45738 | V12: 11670 | W12: TLB-DEG-2024/00027 | X12: GENARA LOPES BÜHLER | Y12: PÚBLICO | Z12: 10014530 | AB12: 2024NE000632 | AC12: 45365 | AD12: =NETWORKDAYS.INTL(Tab_4.DISP_INEX[[#This Row],[DATA RECEBIDO]],Tab_4.DISP_INEX[[#This Row],[DATA FINALIZADO]],1,Lista!$U$3:$U$15) -> 2 | AJ12: https://www.telebras.com.br/wp-content/uploads/2024/12/16.2024NE000632-ZENITE-INFORMACAO-E-CONSULTORIA-SA.pdf | AK12: https://www.telebras.com.br/wp-content/uploads/2026/06/8_TR_Zenite-Informacao-e-Consultoria-SA.pdf | AL12: https://www.telebras.com.br/wp-content/uploads/2026/06/8_JUST_Zenite-Informacao-e-Consultoria-SA.pdf | AM12: https://www.telebras.com.br/wp-content/uploads/2026/06/8_RAT_Zenite-Informacao-e-Consultoria-SA.pdf | AP12: 8 | AQ12: =_xlfn.CONCAT(AP12,"_","TR","_",Tab_4.DISP_INEX[[#This Row],[FORNECEDOR]]) -> 8_TR_Zênite Informação e Consultoria S/A | AR12: =_xlfn.CONCAT(AP12,"_","JUST","_",Tab_4.DISP_INEX[[#This Row],[FORNECEDOR]]) -> 8_JUST_Zênite Informação e Consultoria S/A | AS12: =_xlfn.CONCAT(AP12,"_","RAT","_",Tab_4.DISP_INEX[[#This Row],[FORNECEDOR]]) -> 8_RAT_Zênite Informação e Consultoria S/A
B13: 45370 | C13: FRANCIELE | D13: FINALIZADO | E13: FINALIZADO | F13: TLB-PRO-2024/00922 | G13: 2000-DAFRI | H13: GEOS | I13: Serviços | J13: Participação da Telebras no Simpósio Internacional Especializado em Dinâmica de Vôo Espacial - International Symposium on Space Flight Dynamics (ISSFD). | K13: Inexigibilidade | L13: ADMINISTRATIVO | M13: ATP Specials BV | O13: Nota de Empenho | P13: 2024NE000628 | Q13: 2024NE000628 | R13: 2024NE000628 | S13: 45373 | T13: 45373 | U13: 45373 | V13: 6927.9 | W13: TLB-DEG-2024/00025 | X13: MÁRCIA MANUELA MEDRADO NUNES | Y13: PÚBLICO | Z13: 10014538 | AB13: 2024NE000628 | AC13: 45370 | AD13: =NETWORKDAYS.INTL(Tab_4.DISP_INEX[[#This Row],[DATA RECEBIDO]],Tab_4.DISP_INEX[[#This Row],[DATA FINALIZADO]],1,Lista!$U$3:$U$15) -> 1 | AE13: FRANCIELE | AF13: EVENTO | AJ13: https://www.telebras.com.br/wp-content/uploads/2024/12/13.2024NE000628-ATP-SPECIALS-BV.pdf | AK13: https://www.telebras.com.br/wp-content/uploads/2026/06/9_TR_ATP-Specials-BV.pdf | AL13: https://www.telebras.com.br/wp-content/uploads/2026/06/9_JUST_ATP-Specials-BV.pdf | AM13: https://www.telebras.com.br/wp-content/uploads/2026/06/9_RAT_ATP-Specials-BV.pdf | AP13: 9 | AQ13: =_xlfn.CONCAT(AP13,"_","TR","_",Tab_4.DISP_INEX[[#This Row],[FORNECEDOR]]) -> 9_TR_ATP Specials BV | AR13: =_xlfn.CONCAT(AP13,"_","JUST","_",Tab_4.DISP_INEX[[#This Row],[FORNECEDOR]]) -> 9_JUST_ATP Specials BV | AS13: =_xlfn.CONCAT(AP13,"_","RAT","_",Tab_4.DISP_INEX[[#This Row],[FORNECEDOR]]) -> 9_RAT_ATP Specials BV
B14: 45372 | C14: FRANCIELE | D14: FINALIZADO | E14: FINALIZADO | F14: TLB-PRO-2024/01130 | G14: 2000-DAFRI | H14: GIRC | I14: Serviços | J14: Associação da Telebras ao Instituto Brasileiro de Governança Corporativa - IBGC | K14: Inexigibilidade | L14: ADMINISTRATIVO | M14: Instituto Brasileiro de Governança Corporativa - IBGC | N14: 01.082.331/0001-80 | O14: Contrato | P14: 2024NE000837 | Q14: TLB-CTR-2024/00045 | R14: TLB-AUT-2024/10835 | S14: 45463 | T14: 45463 | U14: 45657 | V14: 17289 | W14: TLB-DEG-2024/00070 | X14: ANTÔNIO CELSON DE JESUS NERIS | Y14: PÚBLICO | Z14: 10014520 | AA14: 10003951 | AB14: TLB-CTR-2024/00045 | AC14: 45373 | AD14: =NETWORKDAYS.INTL(Tab_4.DISP_INEX[[#This Row],[DATA RECEBIDO]],Tab_4.DISP_INEX[[#This Row],[DATA FINALIZADO]],1,Lista!$U$3:$U$15) -> 2 | AE14: FRANCIELE | AF14: ASSOCIAÇÃO | AJ14: https://www.telebras.com.br/wp-content/uploads/2024/12/29.-TLB-CTR-2024-00045-INSTITUTO-BRASILEIRO-DE-GOVERNANCA-CORPORATIVA-IBGC.pdf | AK14: https://www.telebras.com.br/wp-content/uploads/2026/06/10_TR_-Instituto-Brasileiro-de-Governanca-Corporativa-IBGC.pdf | AL14: https://www.telebras.com.br/wp-content/uploads/2026/06/10_JUST_-Instituto-Brasileiro-de-Governanca-Corporativa-IBGC.pdf | AM14: https://www.telebras.com.br/wp-content/uploads/2026/06/10_RAT_-Instituto-Brasileiro-de-Governanca-Corporativa-IBGC.pdf | AP14: 10 | AQ14: =_xlfn.CONCAT(AP14,"_","TR","_",Tab_4.DISP_INEX[[#This Row],[FORNECEDOR]]) -> 10_TR_ Instituto Brasileiro de Governança Corporativa - IBGC | AR14: =_xlfn.CONCAT(AP14,"_","JUST","_",Tab_4.DISP_INEX[[#This Row],[FORNECEDOR]]) -> 10_JUST_ Instituto Brasileiro de Governança Corporativa - IBGC | AS14: =_xlfn.CONCAT(AP14,"_","RAT","_",Tab_4.DISP_INEX[[#This Row],[FORNECEDOR]]) -> 10_RAT_ Instituto Brasileiro de Governança Corporativa - IBGC
B15: 45372 | C15: ROSILDA | D15: FINALIZADO | E15: FINALIZADO | F15: TLB-PRO-2024/00728 | G15: 2000-DAFRI | H15: GD | I15: Serviços | J15: Consultoria para Evolução da Gestão do Conhecimento | K15: Inexigibilidade | L15: ADMINISTRATIVO | M15: IMPAKT CONSULTORIA S/S LIMITADA | N15: 08.170.564/0001-84 | O15: Nota de Empenho | P15: 2024NE000824 | Q15: 2024NE000824 | R15: TLB-ASS-2024/16668 | S15: 45628 | T15: 45628 | U15: 45811 | V15: 262200 | Y15: PÚBLICO | Z15: 10014500 | AB15: 2024NE000824 | AC15: 45385 | AD15: =NETWORKDAYS.INTL(Tab_4.DISP_INEX[[#This Row],[DATA RECEBIDO]],Tab_4.DISP_INEX[[#This Row],[DATA FINALIZADO]],1,Lista!$U$3:$U$15) -> 9 | AJ15: https://www.telebras.com.br/wp-content/uploads/2026/04/4.-2024NE000824-IMPAKT-CONSULTORIA-1.pdf | AK15: https://www.telebras.com.br/wp-content/uploads/2026/06/11_TR_IMPAKT-CONSULTORIA-SS-LIMITADA.pdf | AL15: https://www.telebras.com.br/wp-content/uploads/2026/06/11_JUST_IMPAKT-CONSULTORIA-SS-LIMITADA.pdf | AM15: https://www.telebras.com.br/wp-content/uploads/2026/06/11_RAT_IMPAKT-CONSULTORIA-SS-LIMITADA.pdf | AP15: 11 | AQ15: =_xlfn.CONCAT(AP15,"_","TR","_",Tab_4.DISP_INEX[[#This Row],[FORNECEDOR]]) -> 11_TR_IMPAKT CONSULTORIA S/S LIMITADA | AR15: =_xlfn.CONCAT(AP15,"_","JUST","_",Tab_4.DISP_INEX[[#This Row],[FORNECEDOR]]) -> 11_JUST_IMPAKT CONSULTORIA S/S LIMITADA | AS15: =_xlfn.CONCAT(AP15,"_","RAT","_",Tab_4.DISP_INEX[[#This Row],[FORNECEDOR]]) -> 11_RAT_IMPAKT CONSULTORIA S/S LIMITADA
B16: 45394 | C16: ROSILDA | D16: FINALIZADO | E16: FINALIZADO | F16: TLB-PRO-2024/01473 | G16: 2000-DAFRI | H16: GCONT | I16: Serviços | J16: Curso de ICMS - Teoria e Prática | K16: Inexigibilidade | L16: ADMINISTRATIVO | M16: IBET Instituto Brasileiro de Estudos Tributários | N16: 63.104.475/0001-48 | O16: Nota de Empenho | P16: 2024NE000684 | Q16: 2024NE000684 | R16: TLB-ASS-2024/06584 | S16: 45407 | T16: 45414 | U16: 45414 | V16: 10500 | W16: TLB-DEG-2024/00044 | X16: ADRYANA RAMOS DE OLIVEIRA | Y16: PÚBLICO | Z16: 10014610 | AB16: 2024NE000684 | AC16: 45415 | AD16: =NETWORKDAYS.INTL(Tab_4.DISP_INEX[[#This Row],[DATA RECEBIDO]],Tab_4.DISP_INEX[[#This Row],[DATA FINALIZADO]],1,Lista!$U$3:$U$15) -> 15 | AF16: CAPACITAÇÃO | AJ16: https://www.telebras.com.br/wp-content/uploads/2024/12/34.2024NE000684-IBET-INSTITUTO-BRASILEIRO-DE-ESTUDOS-TRIBUTARIOS.pdf | AK16: https://www.telebras.com.br/wp-content/uploads/2026/06/12_TR_IBET-Instituto-Brasileiro-de-Estudos-Tributarios.pdf | AL16: https://www.telebras.com.br/wp-content/uploads/2026/06/12_JUST_IBET-Instituto-Brasileiro-de-Estudos-Tributarios.pdf | AM16: https://www.telebras.com.br/wp-content/uploads/2026/06/12_RAT_IBET-Instituto-Brasileiro-de-Estudos-Tributarios.pdf | AP16: 12 | AQ16: =_xlfn.CONCAT(AP16,"_","TR","_",Tab_4.DISP_INEX[[#This Row],[FORNECEDOR]]) -> 12_TR_IBET Instituto Brasileiro de Estudos Tributários | AR16: =_xlfn.CONCAT(AP16,"_","JUST","_",Tab_4.DISP_INEX[[#This Row],[FORNECEDOR]]) -> 12_JUST_IBET Instituto Brasileiro de Estudos Tributários | AS16: =_xlfn.CONCAT(AP16,"_","RAT","_",Tab_4.DISP_INEX[[#This Row],[FORNECEDOR]]) -> 12_RAT_IBET Instituto Brasileiro de Estudos Tributários
B17: 45384 | C17: FRANCIELE | D17: FINALIZADO | E17: FINALIZADO | F17: TLB-PRO-2024/01475 | G17: 2000-DAFRI | H17: GCONT | I17: Serviços | J17: Contratação da capacitação "Formação em PIS e Cofins" | K17: Inexigibilidade | L17: ADMINISTRATIVO | M17: Cenofisco Centro de Capacitação Profissional Ltda | N17: 07.799.454/0001-13 | O17: Nota de Empenho | P17: 2024NE000653 | Q17: 2024NE000653 | R17: 2024NE000653 | S17: 45390 | T17: 45390 | U17: 45390 | V17: 1744 | W17: TLB-DEG-2024/00031 | X17: GLAHICON ROGERIO GREGORIO | Y17: PÚBLICO | Z17: 10014577 | AA17: 10003625 | AB17: 2024NE000653 | AC17: 45385 | AD17: =NETWORKDAYS.INTL(Tab_4.DISP_INEX[[#This Row],[DATA RECEBIDO]],Tab_4.DISP_INEX[[#This Row],[DATA FINALIZADO]],1,Lista!$U$3:$U$15) -> 2 | AE17: ROSILDA | AF17: CAPACITAÇÃO | AJ17: https://www.telebras.com.br/wp-content/uploads/2024/12/17.2024NE000653-CENOFISCO-CENTRO-DE-CAPACITACAO-PROFISSIONAL-LTDA.pdf | AK17: https://www.telebras.com.br/wp-content/uploads/2026/06/13_TR_Cenofisco-Centro-de-Capacitacao-Profissional-Ltda.pdf | AL17: https://www.telebras.com.br/wp-content/uploads/2026/06/13_JUST_Cenofisco-Centro-de-Capacitacao-Profissional-Ltda.pdf | AM17: https://www.telebras.com.br/wp-content/uploads/2026/06/13_RAT_Cenofisco-Centro-de-Capacitacao-Profissional-Ltda.pdf | AP17: 13 | AQ17: =_xlfn.CONCAT(AP17,"_","TR","_",Tab_4.DISP_INEX[[#This Row],[FORNECEDOR]]) -> 13_TR_Cenofisco Centro de Capacitação Profissional Ltda | AR17: =_xlfn.CONCAT(AP17,"_","JUST","_",Tab_4.DISP_INEX[[#This Row],[FORNECEDOR]]) -> 13_JUST_Cenofisco Centro de Capacitação Profissional Ltda | AS17: =_xlfn.CONCAT(AP17,"_","RAT","_",Tab_4.DISP_INEX[[#This Row],[FORNECEDOR]]) -> 13_RAT_Cenofisco Centro de Capacitação Profissional Ltda
B18: 45405 | C18: ROSILDA | D18: FINALIZADO | E18: FINALIZADO | F18: TLB-PRO-2024/01308 | G18: 2000-DAFRI | H18: GIRC | I18: Serviços | J18: Participação no 11º Congresso Internacional de Compliance | K18: Inexigibilidade | L18: ADMINISTRATIVO | M18: LEC Educação e Pesquisa Ltda | N18: 16.457.791/0001-13 | O18: Nota de Empenho | P18: 2024NE000693 | Q18: 2024NE000693 | R18: TLB-ASS-2024/06684 | S18: 45408 | T18: 45414 | U18: 45414 | V18: 18900 | W18: TLB-DEG-2024/00046 | X18: ÉRIKA NEVES OLIVEIRA | Y18: PÚBLICO | Z18: 10014578 | AB18: 2024NE000693 | AC18: 45414 | AD18: =NETWORKDAYS.INTL(Tab_4.DISP_INEX[[#This Row],[DATA RECEBIDO]],Tab_4.DISP_INEX[[#This Row],[DATA FINALIZADO]],1,Lista!$U$3:$U$15) -> 7 | AF18: CAPACITAÇÃO | AJ18: https://www.telebras.com.br/wp-content/uploads/2026/04/5.-2024NE000693-LEC-EDUC-E-PESQUISA-LTDA-1.pdf | AK18: https://www.telebras.com.br/wp-content/uploads/2026/06/14_TR_LEC-Educacao-e-Pesquisa-Ltda.pdf | AL18: https://www.telebras.com.br/wp-content/uploads/2026/06/14_JUST_LEC-Educacao-e-Pesquisa-Ltda.pdf | AM18: https://www.telebras.com.br/wp-content/uploads/2026/06/14_RAT_LEC-Educacao-e-Pesquisa-Ltda.pdf | AP18: 14 | AQ18: =_xlfn.CONCAT(AP18,"_","TR","_",Tab_4.DISP_INEX[[#This Row],[FORNECEDOR]]) -> 14_TR_LEC Educação e Pesquisa Ltda | AR18: =_xlfn.CONCAT(AP18,"_","JUST","_",Tab_4.DISP_INEX[[#This Row],[FORNECEDOR]]) -> 14_JUST_LEC Educação e Pesquisa Ltda | AS18: =_xlfn.CONCAT(AP18,"_","RAT","_",Tab_4.DISP_INEX[[#This Row],[FORNECEDOR]]) -> 14_RAT_LEC Educação e Pesquisa Ltda
B19: 45406 | C19: FRANCIELE | D19: FINALIZADO | E19: FINALIZADO | F19: TLB-PRO-2024/02102 | G19: 3000-DTO | H19: GPM | I19: Serviços | J19: Incluir a Telebras como associada da ABRINT - Associação Brasileira de Provedores de Internet sob o título de parceira- fornecedora. | K19: Inexigibilidade | L19: ADMINISTRATIVO | M19: Associação Brasileira de Provedores de Internet - ABRINT | N19: 11.369.542/0001-52 | O19: Nota de Empenho | P19: 2024NE000820 | Q19: 2024NE000820 | R19: TLB-ASS-2024/08452 | S19: 45439 | T19: 45449 | U19: 45808 | V19: 3600 | W19: TLB-DEG-2024/00059 | X19: MARIANA RODRIGUES BOAVISTA LEITE | Y19: PÚBLICO | Z19: 10014600 | AA19: 10001209 | AB19: 2024NE000820 | AC19: 45414 | AD19: =NETWORKDAYS.INTL(Tab_4.DISP_INEX[[#This Row],[DATA RECEBIDO]],Tab_4.DISP_INEX[[#This Row],[DATA FINALIZADO]],1,Lista!$U$3:$U$15) -> 6 | AJ19: https://www.telebras.com.br/wp-content/uploads/2026/04/6.-2024NE000820-ASSOC-BRAS-PROVEDORES-DE-INTERNET-ABRINT-1.pdf | AK19: - | AL19: - | AM19: - | AP19: 15 | AQ19: =_xlfn.CONCAT(AP19,"_","TR","_",Tab_4.DISP_INEX[[#This Row],[FORNECEDOR]]) -> 15_TR_Associação Brasileira de Provedores de Internet - ABRINT | AR19: =_xlfn.CONCAT(AP19,"_","JUST","_",Tab_4.DISP_INEX[[#This Row],[FORNECEDOR]]) -> 15_JUST_Associação Brasileira de Provedores de Internet - ABRINT | AS19: =_xlfn.CONCAT(AP19,"_","RAT","_",Tab_4.DISP_INEX[[#This Row],[FORNECEDOR]]) -> 15_RAT_Associação Brasileira de Provedores de Internet - ABRINT | AT19: O termo de refência e o objeto é o mesmo do n° 10
B20: 45411 | C20: FRANCIELE | D20: FINALIZADO | E20: FINALIZADO | F20: TLB-PRO-2024/01992 | G20: 2000-DAFRI | H20: GGP | I20: Serviços | J20: Curso T&D | K20: Inexigibilidade | L20: ADMINISTRATIVO | M20: Integração - Escola de Negócios Ltda | N20: 03.493.782/0001-36 | O20: Nota de Empenho | P20: 2024NE000711 | Q20: 2024NE000711 | R20: TLB-ASS-2024/06974 | S20: 45414 | T20: 45415 | U20: 45415 | V20: 5300 | W20: TLB-DEG-2024/00051 | X20: ADRYANA RAMOS DE OLIVEIRA | Y20: PÚBLICO | Z20: 10014616 | AA20: 10002720 | AB20: 2024NE000711 | AC20: 45411 | AD20: =NETWORKDAYS.INTL(Tab_4.DISP_INEX[[#This Row],[DATA RECEBIDO]],Tab_4.DISP_INEX[[#This Row],[DATA FINALIZADO]],1,Lista!$U$3:$U$15) -> 1 | AE20: FRANCIELE | AF20: CAPACITAÇÃO | AJ20: https://www.telebras.com.br/wp-content/uploads/2026/04/7.-2024NE000711-INTEG-ESCOLA-DE-NEGOCIOS-LTDA-1.pdf | AK20: https://www.telebras.com.br/wp-content/uploads/2026/06/16_TR_Integracao-Escola-de-Negocios-Ltda.pdf | AL20: https://www.telebras.com.br/wp-content/uploads/2026/06/16_JUST_Integracao-Escola-de-Negocios-Ltda.pdf | AM20: https://www.telebras.com.br/wp-content/uploads/2026/06/16_RAT_Integracao-Escola-de-Negocios-Ltda.pdf | AP20: 16 | AQ20: =_xlfn.CONCAT(AP20,"_","TR","_",Tab_4.DISP_INEX[[#This Row],[FORNECEDOR]]) -> 16_TR_Integração - Escola de Negócios Ltda | AR20: =_xlfn.CONCAT(AP20,"_","JUST","_",Tab_4.DISP_INEX[[#This Row],[FORNECEDOR]]) -> 16_JUST_Integração - Escola de Negócios Ltda | AS20: =_xlfn.CONCAT(AP20,"_","RAT","_",Tab_4.DISP_INEX[[#This Row],[FORNECEDOR]]) -> 16_RAT_Integração - Escola de Negócios Ltda
B21: 45435 | C21: FRANCIELE | D21: FINALIZADO | E21: FINALIZADO | F21: TLB-PRO-2024/02662 | G21: 2000-DAFRI | H21: GGP | I21: Serviços | J21: Contratação da participação no evento "11º Congresso Internacional de Compliance" | K21: Inexigibilidade | L21: ADMINISTRATIVO | M21: LEC EDUCACAO E PESQUISA LTDA | N21: 16.457.791/0001-13 | O21: Nota de Empenho | P21: 2024NE000822 | Q21: 2024NE000822 | R21: TLB-ASS-2024/08497 | S21: 45440 | T21: 45440 | U21: 45440 | V21: 4905 | W21: TLB-DEG-2024/00057 | X21: ADRYANA RAMOS DE OLIVEIRA | Y21: PÚBLICO | Z21: 10014684 | AA21: 10004029 | AB21: 2024NE000822 | AC21: 45436 | AD21: =NETWORKDAYS.INTL(Tab_4.DISP_INEX[[#This Row],[DATA RECEBIDO]],Tab_4.DISP_INEX[[#This Row],[DATA FINALIZADO]],1,Lista!$U$3:$U$15) -> 2 | AE21: FRANCIELE | AF21: CAPACITAÇÃO | AJ21: https://www.telebras.com.br/wp-content/uploads/2026/04/8.-2024NE000822-LEC-EDUCACAO-E-PESQUISA-LTDA-1.pdf | AK21: https://www.telebras.com.br/wp-content/uploads/2026/06/17_TR_LEC-EDUCACAO-E-PESQUISA-LTDA.pdf | AL21: https://www.telebras.com.br/wp-content/uploads/2026/06/17_JUST_LEC-EDUCACAO-E-PESQUISA-LTDA.pdf | AM21: https://www.telebras.com.br/wp-content/uploads/2026/06/17_RAT_LEC-EDUCACAO-E-PESQUISA-LTDA.pdf | AP21: 17 | AQ21: =_xlfn.CONCAT(AP21,"_","TR","_",Tab_4.DISP_INEX[[#This Row],[FORNECEDOR]]) -> 17_TR_LEC EDUCACAO E PESQUISA LTDA | AR21: =_xlfn.CONCAT(AP21,"_","JUST","_",Tab_4.DISP_INEX[[#This Row],[FORNECEDOR]]) -> 17_JUST_LEC EDUCACAO E PESQUISA LTDA | AS21: =_xlfn.CONCAT(AP21,"_","RAT","_",Tab_4.DISP_INEX[[#This Row],[FORNECEDOR]]) -> 17_RAT_LEC EDUCACAO E PESQUISA LTDA
B22: 45470 | C22: FRANCIELE | D22: FINALIZADO | E22: FINALIZADO | F22: TLB-PRO-2024/03371 | G22: 2000-DAFRI | H22: GGP | I22: Serviços | J22: Contratação da participação no evento "GDI Connect 2024 DF" | K22: Inexigibilidade | L22: ADMINISTRATIVO | M22: PS Treinamento Profissional e Consultoria Empresarial Ltda | N22: 38.593.731/0001-60 | O22: Nota de Empenho | P22: 2024NE000885 | Q22: 2024NE000885 | R22: TLB-ASS-2024/10193 | S22: 45474 | T22: 45474 | U22: 45474 | V22: 397 | W22: TLB-DEG-2024/00075 | X22: VICTOR COELHO ASSUNÇÃO CARNEIRO | Y22: PÚBLICO | Z22: 10014783 | AA22: 10004052 | AB22: 2024NE000885 | AC22: 45470 | AD22: =NETWORKDAYS.INTL(Tab_4.DISP_INEX[[#This Row],[DATA RECEBIDO]],Tab_4.DISP_INEX[[#This Row],[DATA FINALIZADO]],1,Lista!$U$3:$U$15) -> 1 | AE22: FRANCIELE | AF22: CAPACITAÇÃO | AJ22: https://www.telebras.com.br/wp-content/uploads/2026/04/10.-2024NE000940-SPACE-DATA-ASSOCIATION-1.pdf | AK22: https://www.telebras.com.br/wp-content/uploads/2026/06/18_TR_PS-Treinamento-Profissional-e-Consultoria-Empresarial-Ltda.pdf | AL22: https://www.telebras.com.br/wp-content/uploads/2026/06/18_JUST_PS-Treinamento-Profissional-e-Consultoria-Empresarial-Ltda.pdf | AM22: https://www.telebras.com.br/wp-content/uploads/2026/06/18_RAT_PS-Treinamento-Profissional-e-Consultoria-Empresarial-Ltda.pdf | AP22: 18 | AQ22: =_xlfn.CONCAT(AP22,"_","TR","_",Tab_4.DISP_INEX[[#This Row],[FORNECEDOR]]) -> 18_TR_PS Treinamento Profissional e Consultoria Empresarial Ltda | AR22: =_xlfn.CONCAT(AP22,"_","JUST","_",Tab_4.DISP_INEX[[#This Row],[FORNECEDOR]]) -> 18_JUST_PS Treinamento Profissional e Consultoria Empresarial Ltda | AS22: =_xlfn.CONCAT(AP22,"_","RAT","_",Tab_4.DISP_INEX[[#This Row],[FORNECEDOR]]) -> 18_RAT_PS Treinamento Profissional e Consultoria Empresarial Ltda
B23: 45511 | C23: FRANCIELE | D23: FINALIZADO | E23: FINALIZADO | F23: TLB-PRO-2024/01102 | G23: 3000-DTO | H23: GEOS | I23: Serviços | J23: Associação da Telebras à Space Data Association – DAS | K23: Inexigibilidade | L23: ADMINISTRATIVO | M23: Space Data Association | O23: Nota de Empenho | P23: 2024NE000940 | Q23: 2024NE000940 | R23: TLB-ASS-2024/13821 | S23: 45530 | T23: 45533 | U23: 45898 | V23: 75948.05 | W23: TLB-DEG-2024/00105 | X23: MÁRCIA MANUELA MEDRADO NUNES | Y23: PÚBLICO | Z23: 10014763 | AB23: 2024NE000940 | AC23: 45516 | AD23: =NETWORKDAYS.INTL(Tab_4.DISP_INEX[[#This Row],[DATA RECEBIDO]],Tab_4.DISP_INEX[[#This Row],[DATA FINALIZADO]],1,Lista!$U$3:$U$15) -> 4 | AE23: FRANCIELE | AF23: ASSOCIAÇÃO | AJ23: https://www.telebras.com.br/wp-content/uploads/2026/04/10.-2024NE000940-SPACE-DATA-ASSOCIATION-1.pdf | AK23: https://www.telebras.com.br/wp-content/uploads/2026/06/19_TR_Space-Data-Association.pdf | AL23: https://www.telebras.com.br/wp-content/uploads/2026/06/19_JUST_Space-Data-Association.pdf | AM23: https://www.telebras.com.br/wp-content/uploads/2026/06/19_RAT_Space-Data-Association.pdf | AP23: 19 | AQ23: =_xlfn.CONCAT(AP23,"_","TR","_",Tab_4.DISP_INEX[[#This Row],[FORNECEDOR]]) -> 19_TR_Space Data Association | AR23: =_xlfn.CONCAT(AP23,"_","JUST","_",Tab_4.DISP_INEX[[#This Row],[FORNECEDOR]]) -> 19_JUST_Space Data Association | AS23: =_xlfn.CONCAT(AP23,"_","RAT","_",Tab_4.DISP_INEX[[#This Row],[FORNECEDOR]]) -> 19_RAT_Space Data Association
B24: 45476 | C24: FRANCIELE | D24: FINALIZADO | E24: FINALIZADO | F24: TLB-PRO-2024/02467 | G24: 2000-DAFRI | H24: GPM | I24: Serviços | J24: Participação da Telebras, por meio de ação promocional, no Seminário Nacional de TIC para a Gestão Pública SECOP 2024, evento organizado exclusivamente pela Associação Brasileira de Entidades Estaduais de Tecnologia da Informação e Comunicação ABEP. | K24: Inexigibilidade | L24: ADMINISTRATIVO | M24: Associação Brasileira de Entidades Estaduais e Públicas de tecnologia da Infrmção e comunicação ES - ABEP | N24: 77.639.433/0001-16 | O24: Contrato | P24: 2024NE000896 | Q24: TLB-CTR-2024/00056 | R24: TLB-AUT-2024/12823 | S24: 45491 | T24: 45491 | U24: 45657 | V24: 59988 | W24: TLB-DEG-2024/00080 | X24: MARIANA RODRIGUES BOAVISTA LEITE | Y24: PÚBLICO | Z24: 10014621 | AA24: 10001625 | AB24: TLB-CTR-2024/00056 | AC24: 45476 | AD24: =NETWORKDAYS.INTL(Tab_4.DISP_INEX[[#This Row],[DATA RECEBIDO]],Tab_4.DISP_INEX[[#This Row],[DATA FINALIZADO]],1,Lista!$U$3:$U$15) -> 1 | AE24: FRANCIELE | AF24: EVENTO | AJ24: https://www.telebras.com.br/wp-content/uploads/2024/12/41.2024NE000896-ASSOCIACAO-BRASILEIRA-DE-ENTIDADES-ESTADUAIS.pdf | AK24: https://www.telebras.com.br/wp-content/uploads/2026/06/20_TR_Associacao-Brasileira-de-Entidades-Estaduais-e-Publicas-de-tecnologia-da-Infrmcao-e-comunicacao-ES-ABEP.pdf | AL24: https://www.telebras.com.br/wp-content/uploads/2026/06/20_JUST_Associacao-Brasileira-de-Entidades-Estaduais-e-Publicas-de-tecnologia-da-Infrmcao-e-comunicacao-ES-ABEP.pdf | AM24: https://www.telebras.com.br/wp-content/uploads/2026/06/20_RAT_Associacao-Brasileira-de-Entidades-Estaduais-e-Publicas-de-tecnologia-da-Infrmcao-e-comunicacao-ES-ABEP.pdf | AP24: 20 | AQ24: =_xlfn.CONCAT(AP24,"_","TR","_",Tab_4.DISP_INEX[[#This Row],[FORNECEDOR]]) -> 20_TR_Associação Brasileira de Entidades Estaduais e Públicas de tecnologia da Infrmção e comunicação ES - ABEP | AR24: =_xlfn.CONCAT(AP24,"_","JUST","_",Tab_4.DISP_INEX[[#This Row],[FORNECEDOR]]) -> 20_JUST_Associação Brasileira de Entidades Estaduais e Públicas de tecnologia da Infrmção e comunicação ES - ABEP | AS24: =_xlfn.CONCAT(AP24,"_","RAT","_",Tab_4.DISP_INEX[[#This Row],[FORNECEDOR]]) -> 20_RAT_Associação Brasileira de Entidades Estaduais e Públicas de tecnologia da Infrmção e comunicação ES - ABEP
B25: 45490 | C25: FRANCIELE | D25: FINALIZADO | E25: FINALIZADO | F25: TLB-PRO-2024/03684 | G25: 2000-DAFRI | H25: CIPA | I25: Serviços | J25: Contratação de empresa especializada para a prestação de serviço de treinamento de Prevenção de Acidentes do Trabalho e de Assédio, para 10 (dez) membros da Comissão interna de Prevenção de Acidentes e de Assédio (CIPA) - Gestão 2024/2025 | K25: Inexigibilidade | L25: ADMINISTRATIVO | M25: Bioseg Brasília Soluções em Segurança e Medicina do Trabalho Ltda | N25: 46.590.489/0001-08 | O25: Nota de Empenho | P25: 2024NE000909 | Q25: 2024NE000909 | R25: TLB-ASS-2024/11469 | S25: 45503 | T25: 45503 | U25: 45503 | V25: 1900 | W25: TLB-DEG-2024/00085 | X25: ROSILDA FERREIRA DA CUNHA | Y25: PÚBLICO | Z25: 10014798 | AA25: 10003765 | AB25: 2024NE000909 | AC25: 45491 | AD25: =NETWORKDAYS.INTL(Tab_4.DISP_INEX[[#This Row],[DATA RECEBIDO]],Tab_4.DISP_INEX[[#This Row],[DATA FINALIZADO]],1,Lista!$U$3:$U$15) -> 2 | AE25: FRANCIELE | AF25: CAPACITAÇÃO | AJ25: https://www.telebras.com.br/wp-content/uploads/2024/12/39.2024NE000909-Bioseg-Brasilia-Solucoes-em-Seguranca-e-Medicina-do-Trabalho-Ltda.pdf | AK25: https://www.telebras.com.br/wp-content/uploads/2026/06/21_TR_Bioseg-Brasilia-Solucoes-em-Seguranca-e-Medicina-do-Trabalho-Ltda.pdf | AL25: https://www.telebras.com.br/wp-content/uploads/2026/06/21_JUST_Bioseg-Brasilia-Solucoes-em-Seguranca-e-Medicina-do-Trabalho-Ltda.pdf | AM25: https://www.telebras.com.br/wp-content/uploads/2026/06/21_RAT_Bioseg-Brasilia-Solucoes-em-Seguranca-e-Medicina-do-Trabalho-Ltda.pdf | AP25: 21 | AQ25: =_xlfn.CONCAT(AP25,"_","TR","_",Tab_4.DISP_INEX[[#This Row],[FORNECEDOR]]) -> 21_TR_Bioseg Brasília Soluções em Segurança e Medicina do Trabalho Ltda | AR25: =_xlfn.CONCAT(AP25,"_","JUST","_",Tab_4.DISP_INEX[[#This Row],[FORNECEDOR]]) -> 21_JUST_Bioseg Brasília Soluções em Segurança e Medicina do Trabalho Ltda | AS25: =_xlfn.CONCAT(AP25,"_","RAT","_",Tab_4.DISP_INEX[[#This Row],[FORNECEDOR]]) -> 21_RAT_Bioseg Brasília Soluções em Segurança e Medicina do Trabalho Ltda
B26: 45504 | C26: FRANCIELE | D26: FINALIZADO | E26: FINALIZADO | F26: TLB-PRO-2024/03973 | G26: 2000-DAFRI | H26: GGP | I26: Serviços | J26: Contratação da capacitação "AUDI 2 EOP" e associação ao Instituto dos Auditores Internos do Brasil | K26: Inexigibilidade | L26: ADMINISTRATIVO | M26: Instituto dos Auditores Internos do Brasil | N26: 62.070.115/0001-00 | O26: Nota de Empenho | P26: 2024NE000920 | Q26: 2024NE000920 | R26: TLB-ASS-2024/12082 | S26: 45513 | T26: 45518 | U26: 45518 | V26: 8250 | W26: TLB-DEG-2024/00093 | X26: ADRYANA RAMOS DE OLIVEIRA | Y26: PÚBLICO | Z26: 10014830 | AA26: 10004111 | AB26: 2024NE000920 | AC26: 45509 | AD26: =NETWORKDAYS.INTL(Tab_4.DISP_INEX[[#This Row],[DATA RECEBIDO]],Tab_4.DISP_INEX[[#This Row],[DATA FINALIZADO]],1,Lista!$U$3:$U$15) -> 4 | AE26: FRANCIELE | AF26: CAPACITAÇÃO | AJ26: https://www.telebras.com.br/wp-content/uploads/2026/04/11.-2024NE000920-INSTITUTO-DOS-AUDITORES-INTERNOS-DO-BRASIL-1.pdf | AK26: https://www.telebras.com.br/wp-content/uploads/2026/06/22_TR_Instituto-dos-Auditores-Internos-do-Brasil.pdf | AL26: https://www.telebras.com.br/wp-content/uploads/2026/06/22_JUST_Instituto-dos-Auditores-Internos-do-Brasil.pdf | AM26: https://www.telebras.com.br/wp-content/uploads/2026/06/22_RAT_Instituto-dos-Auditores-Internos-do-Brasil.pdf | AP26: 22 | AQ26: =_xlfn.CONCAT(AP26,"_","TR","_",Tab_4.DISP_INEX[[#This Row],[FORNECEDOR]]) -> 22_TR_Instituto dos Auditores Internos do Brasil | AR26: =_xlfn.CONCAT(AP26,"_","JUST","_",Tab_4.DISP_INEX[[#This Row],[FORNECEDOR]]) -> 22_JUST_Instituto dos Auditores Internos do Brasil | AS26: =_xlfn.CONCAT(AP26,"_","RAT","_",Tab_4.DISP_INEX[[#This Row],[FORNECEDOR]]) -> 22_RAT_Instituto dos Auditores Internos do Brasil
B27: 45484 | C27: ROSILDA | D27: FINALIZADO | E27: FINALIZADO | F27: TLB-PRO-2024/02951 | G27: 2000-DAFRI | H27: GGP | I27: Serviços | J27: Participação da GGP/DAFRI no CONARH 2024 - Congresso Nacional de Gestão de Pessoas. | K27: Inexigibilidade | L27: ADMINISTRATIVO | M27: Associação Brasileira de Recursos Humanos | N27: 43.456.425/0001-12 | O27: Nota de Empenho | P27: 2024NE000895 | Q27: 2024NE000895 | R27: TLB-ASS-2024/11013 | S27: 45490 | T27: 45490 | U27: 45490 | V27: 13760 | W27: TLB-DEG-2024/00082 | X27: ADRYANA RAMOS DE OLIVEIRA | Y27: PÚBLICO | Z27: 10014768 | AB27: 2024NE000895 | AC27: 45495 | AD27: =NETWORKDAYS.INTL(Tab_4.DISP_INEX[[#This Row],[DATA RECEBIDO]],Tab_4.DISP_INEX[[#This Row],[DATA FINALIZADO]],1,Lista!$U$3:$U$15) -> 8 | AJ27: https://www.telebras.com.br/wp-content/uploads/2024/12/42.2024NE000895-ASSOCIACAO-BRASILEIRA-DE-RECURSOS-HUMANOS.pdf | AK27: https://www.telebras.com.br/wp-content/uploads/2026/06/23_TR_-Associacao-Brasileira-de-Recursos-Humanos.pdf | AL27: https://www.telebras.com.br/wp-content/uploads/2026/06/23_JUST_-Associacao-Brasileira-de-Recursos-Humanos.pdf | AM27: https://www.telebras.com.br/wp-content/uploads/2026/06/23_RAT_-Associacao-Brasileira-de-Recursos-Humanos.pdf | AP27: 23 | AQ27: =_xlfn.CONCAT(AP27,"_","TR","_",Tab_4.DISP_INEX[[#This Row],[FORNECEDOR]]) -> 23_TR_ Associação Brasileira de Recursos Humanos | AR27: =_xlfn.CONCAT(AP27,"_","JUST","_",Tab_4.DISP_INEX[[#This Row],[FORNECEDOR]]) -> 23_JUST_ Associação Brasileira de Recursos Humanos | AS27: =_xlfn.CONCAT(AP27,"_","RAT","_",Tab_4.DISP_INEX[[#This Row],[FORNECEDOR]]) -> 23_RAT_ Associação Brasileira de Recursos Humanos
B28: 45504 | C28: ROSILDA | D28: FINALIZADO | E28: FINALIZADO | F28: TLB-PRO-2024/02910 | G28: 2000-DAFRI | H28: GGP | I28: Serviços | J28: Associação/Filiação da Telebras à Sociedade Brasileira de Gestão do Conhecimento - SBGC. | K28: Inexigibilidade | L28: ADMINISTRATIVO | M28: Associação Brasileira de Gestão do Conhecimento - SBGC | N28: 04.471.222/0001-43 | O28: Nota de Empenho | P28: 2024NE000948 | Q28: 2024NE000948 | R28: TLB-ASS-2024/13048 | S28: 45539 | T28: 45551 | U28: 45924 | V28: 6500 | W28: TLB-DEG-2024/00110 | X28: CAMILA DANIELA LIMA DE SOUZA GOMES | Y28: PÚBLICO | Z28: 10014747 | AB28: TLB-ASS-2024/13480 | AC28: 45565 | AD28: =NETWORKDAYS.INTL(Tab_4.DISP_INEX[[#This Row],[DATA RECEBIDO]],Tab_4.DISP_INEX[[#This Row],[DATA FINALIZADO]],1,Lista!$U$3:$U$15) -> 44 | AJ28: https://www.telebras.com.br/wp-content/uploads/2026/04/13.-2024NE000948-ASSOC-BRAS-DE-GESTAO-CONHECIMENTO-SBGC-1.pdf | AK28: https://www.telebras.com.br/wp-content/uploads/2026/06/24_TR_Associacao-Brasileira-de-Gestao-do-Conhecimento-SBGC.pdf | AL28: https://www.telebras.com.br/wp-content/uploads/2026/06/24_JUST_Associacao-Brasileira-de-Gestao-do-Conhecimento-SBGC.pdf | AM28: https://www.telebras.com.br/wp-content/uploads/2026/06/24_RAT_Associacao-Brasileira-de-Gestao-do-Conhecimento-SBGC.pdf | AP28: 24 | AQ28: =_xlfn.CONCAT(AP28,"_","TR","_",Tab_4.DISP_INEX[[#This Row],[FORNECEDOR]]) -> 24_TR_Associação Brasileira de Gestão do Conhecimento - SBGC | AR28: =_xlfn.CONCAT(AP28,"_","JUST","_",Tab_4.DISP_INEX[[#This Row],[FORNECEDOR]]) -> 24_JUST_Associação Brasileira de Gestão do Conhecimento - SBGC | AS28: =_xlfn.CONCAT(AP28,"_","RAT","_",Tab_4.DISP_INEX[[#This Row],[FORNECEDOR]]) -> 24_RAT_Associação Brasileira de Gestão do Conhecimento - SBGC
B29: 45506 | C29: FRANCIELE | D29: FINALIZADO | E29: FINALIZADO | F29: TLB-PRO-2024/04037 | G29: 2000-DAFRI | H29: GGP | I29: Serviços | J29: Curso Governance Officer oferecido pelo Instituto Brasileiro de Governança | K29: Inexigibilidade | L29: ADMINISTRATIVO | M29: Instituto Brasileiro de Governança Corporativa | N29: 01.082.331/0001-80 | O29: Nota de Empenho | P29: 2024NE000915 | Q29: 2024NE000915 | R29: TLB-ASS-2024/11845 | S29: 45510 | T29: 45511 | U29: 45511 | V29: 16230 | W29: TLB-DEG-2024/00088 | X29: ALLYNE CUNHA DE OLIVEIRA | Y29: PÚBLICO | Z29: 10014842 | AA29: 10003951 | AB29: 2024NE000915 | AC29: 45506 | AD29: =NETWORKDAYS.INTL(Tab_4.DISP_INEX[[#This Row],[DATA RECEBIDO]],Tab_4.DISP_INEX[[#This Row],[DATA FINALIZADO]],1,Lista!$U$3:$U$15) -> 1 | AE29: FRANCIELE | AF29: CAPACITAÇÃO | AJ29: https://www.telebras.com.br/wp-content/uploads/2026/04/14.-2024NE000915-INST-BRAS-DE-GOVERNANCA-CORPORATIVA-1.pdf | AK29: https://www.telebras.com.br/wp-content/uploads/2026/06/25_TR_Instituto-Brasileiro-de-Governanca-Corporativa.pdf | AL29: https://www.telebras.com.br/wp-content/uploads/2026/06/25_JUST_Instituto-Brasileiro-de-Governanca-Corporativa.pdf | AM29: https://www.telebras.com.br/wp-content/uploads/2026/06/25_RAT_Instituto-Brasileiro-de-Governanca-Corporativa.pdf | AP29: 25 | AQ29: =_xlfn.CONCAT(AP29,"_","TR","_",Tab_4.DISP_INEX[[#This Row],[FORNECEDOR]]) -> 25_TR_Instituto Brasileiro de Governança Corporativa | AR29: =_xlfn.CONCAT(AP29,"_","JUST","_",Tab_4.DISP_INEX[[#This Row],[FORNECEDOR]]) -> 25_JUST_Instituto Brasileiro de Governança Corporativa | AS29: =_xlfn.CONCAT(AP29,"_","RAT","_",Tab_4.DISP_INEX[[#This Row],[FORNECEDOR]]) -> 25_RAT_Instituto Brasileiro de Governança Corporativa
B30: 45525 | C30: FRANCIELE | D30: FINALIZADO | E30: FINALIZADO | F30: TLB-PRO-2024/04040 | G30: 2000-DAFRI | H30: GGP | I30: Serviços | J30: Capacitação Controladoria | K30: Inexigibilidade | L30: ADMINISTRATIVO | M30: Fundação Getulio Vargas | N30: 33.641.663/0001-44 | O30: Nota de Empenho | P30: 2024NE000946 | Q30: 2024NE000946 | R30: TLB-ASS-2024/12840 | S30: 45533 | T30: 45534 | U30: 45534 | V30: 2992.8 | W30: TLB-DEG-2024/00106 | X30: HUGO PORTIERI PIGNATTI | Y30: PÚBLICO | Z30: 10014881 | AA30: 10002313 | AB30: 2024NE000946 | AC30: 45530 | AD30: =NETWORKDAYS.INTL(Tab_4.DISP_INEX[[#This Row],[DATA RECEBIDO]],Tab_4.DISP_INEX[[#This Row],[DATA FINALIZADO]],1,Lista!$U$3:$U$15) -> 4 | AE30: FRANCIELE | AF30: CAPACITAÇÃO | AJ30: https://www.telebras.com.br/wp-content/uploads/2025/02/68.2024NE000946-Fundacao-Getulio-Vargas.pdf | AK30: https://www.telebras.com.br/wp-content/uploads/2026/06/26_TR_Fundacao-Getulio-Vargas.pdf | AL30: https://www.telebras.com.br/wp-content/uploads/2026/06/26_JUST_Fundacao-Getulio-Vargas.pdf | AM30: https://www.telebras.com.br/wp-content/uploads/2026/06/26_RAT_Fundacao-Getulio-Vargas.pdf | AP30: 26 | AQ30: =_xlfn.CONCAT(AP30,"_","TR","_",Tab_4.DISP_INEX[[#This Row],[FORNECEDOR]]) -> 26_TR_Fundação Getulio Vargas | AR30: =_xlfn.CONCAT(AP30,"_","JUST","_",Tab_4.DISP_INEX[[#This Row],[FORNECEDOR]]) -> 26_JUST_Fundação Getulio Vargas | AS30: =_xlfn.CONCAT(AP30,"_","RAT","_",Tab_4.DISP_INEX[[#This Row],[FORNECEDOR]]) -> 26_RAT_Fundação Getulio Vargas
B31: 45559 | C31: FRANCIELE | D31: FINALIZADO | E31: FINALIZADO | F31: TLB-PRO-2024/04850 | G31: 2000-DAFRI | H31: GGP | I31: Serviços | J31: Capacitação Controladoria | K31: Inexigibilidade | L31: ADMINISTRATIVO | M31: Fundação Getulio Vargas | N31: 33.641.663/0001-44 | O31: Nota de Empenho | P31: 2024NE001135 | Q31: 2024NE001135 | R31: TLB-ASS-2024/17513 | S31: 45642 | T31: 45568 | U31: 45568 | V31: 2992.8 | W31: TLB-DEG-2024/00117 | X31: HUGO PORTIERI PIGNATTI | Y31: PÚBLICO | Z31: 10014941 | AA31: 10002313 | AB31: 2024NE000971 | AC31: 45561 | AD31: =NETWORKDAYS.INTL(Tab_4.DISP_INEX[[#This Row],[DATA RECEBIDO]],Tab_4.DISP_INEX[[#This Row],[DATA FINALIZADO]],1,Lista!$U$3:$U$15) -> 3 | AE31: FRANCIELE | AF31: CAPACITAÇÃO | AJ31: https://www.telebras.com.br/wp-content/uploads/2026/04/15.-2024NE001135-FUNDACAO-GETULIO-VARGAS-1.pdf | AK31: https://www.telebras.com.br/wp-content/uploads/2026/06/27_TR_Fundacao-Getulio-Vargas.pdf | AL31: https://www.telebras.com.br/wp-content/uploads/2026/06/27_JUST_Fundacao-Getulio-Vargas.pdf | AM31: https://www.telebras.com.br/wp-content/uploads/2026/06/27_RAT_Fundacao-Getulio-Vargas.pdf | AP31: 27 | AQ31: =_xlfn.CONCAT(AP31,"_","TR","_",Tab_4.DISP_INEX[[#This Row],[FORNECEDOR]]) -> 27_TR_Fundação Getulio Vargas | AR31: =_xlfn.CONCAT(AP31,"_","JUST","_",Tab_4.DISP_INEX[[#This Row],[FORNECEDOR]]) -> 27_JUST_Fundação Getulio Vargas | AS31: =_xlfn.CONCAT(AP31,"_","RAT","_",Tab_4.DISP_INEX[[#This Row],[FORNECEDOR]]) -> 27_RAT_Fundação Getulio Vargas
B32: 45566 | C32: FRANCIELE | D32: FINALIZADO | E32: FINALIZADO | F32: TLB-PRO-2024/05179 | G32: 2000-DAFRI | H32: GGP | I32: Serviços | J32: 25º Congresso IBGC - Cultura de Governança e os Desafios do Brasil | K32: Inexigibilidade | L32: ADMINISTRATIVO | M32: Instituto Brasileiro de Governança Corporativa | N32: 01.082.331/0001-80 | O32: Nota de Empenho | P32: 2024NE000972 | Q32: 2024NE000972 | R32: TLB-ASS-2024/14022 | S32: 02/10/2024 | T32: 45568 | U32: 45568 | V32: 22610 | W32: TLB-DEG-2024/00116 | X32: ADRYANA RAMOS DE OLIVEIRA | Y32: PÚBLICO | Z32: 10014955 | AA32: 10003951 | AB32: 2024NE000972 | AC32: 45566 | AD32: =NETWORKDAYS.INTL(Tab_4.DISP_INEX[[#This Row],[DATA RECEBIDO]],Tab_4.DISP_INEX[[#This Row],[DATA FINALIZADO]],1,Lista!$U$3:$U$15) -> 1 | AE32: FRANCIELE | AF32: EVENTO | AJ32: https://www.telebras.com.br/wp-content/uploads/2024/12/56.2024NE000972-INSTITUTO-BRASILEIRO-DE-GOVERNANCA-CORPORATIVA.pdf | AK32: https://www.telebras.com.br/wp-content/uploads/2026/06/28_TR_Instituto-Brasileiro-de-Governanca-Corporativa.pdf | AL32: https://www.telebras.com.br/wp-content/uploads/2026/06/28_JUST_Instituto-Brasileiro-de-Governanca-Corporativa.pdf | AM32: https://www.telebras.com.br/wp-content/uploads/2026/06/28_RAT_Instituto-Brasileiro-de-Governanca-Corporativa.pdf | AP32: 28 | AQ32: =_xlfn.CONCAT(AP32,"_","TR","_",Tab_4.DISP_INEX[[#This Row],[FORNECEDOR]]) -> 28_TR_Instituto Brasileiro de Governança Corporativa | AR32: =_xlfn.CONCAT(AP32,"_","JUST","_",Tab_4.DISP_INEX[[#This Row],[FORNECEDOR]]) -> 28_JUST_Instituto Brasileiro de Governança Corporativa | AS32: =_xlfn.CONCAT(AP32,"_","RAT","_",Tab_4.DISP_INEX[[#This Row],[FORNECEDOR]]) -> 28_RAT_Instituto Brasileiro de Governança Corporativa
B33: 45573 | C33: FRANCIELE | D33: FINALIZADO | E33: FINALIZADO | F33: TLB-PRO-2024/04517 | G33: 2000-DAFRI | H33: GGP | I33: Serviços | J33: Capacitação NRs 06, 10, 12, 20 e 35 | K33: Inexigibilidade | L33: ADMINISTRATIVO | M33: Bioseg Brasília Soluções em Segurança e Medicina do Trabalho Ltda | N33: 46.590.489/0001-08 | O33: Nota de Empenho | P33: 2024NE000985 | Q33: 2024NE000985 | R33: TLB-ASS-2024/14431 | S33: 45576 | T33: 45580 | U33: 45580 | V33: 15100 | W33: TLB-DEG-2024/00118 | X33: ADRYANA RAMOS DE OLIVEIRA | Y33: PÚBLICO | Z33: 10014956 | AA33: 10003765 | AB33: 2024NE000985 | AC33: 45574 | AD33: =NETWORKDAYS.INTL(Tab_4.DISP_INEX[[#This Row],[DATA RECEBIDO]],Tab_4.DISP_INEX[[#This Row],[DATA FINALIZADO]],1,Lista!$U$3:$U$15) -> 2 | AE33: FRANCIELE | AF33: CAPACITAÇÃO | AJ33: https://www.telebras.com.br/wp-content/uploads/2024/12/58.2024NE000985-Bioseg-Brasilia-Solucoes-em-Seguranca-e-Medicina-do-Trabalho-Ltda.pdf | AK33: https://www.telebras.com.br/wp-content/uploads/2026/06/29_TR_Bioseg-Brasilia-Solucoes-em-Seguranca-e-Medicina-do-Trabalho-Ltda.pdf | AL33: https://www.telebras.com.br/wp-content/uploads/2026/06/29_JUST_Bioseg-Brasilia-Solucoes-em-Seguranca-e-Medicina-do-Trabalho-Ltda.pdf | AM33: https://www.telebras.com.br/wp-content/uploads/2026/06/29_RAT_Bioseg-Brasilia-Solucoes-em-Seguranca-e-Medicina-do-Trabalho-Ltda.pdf | AP33: 29 | AQ33: =_xlfn.CONCAT(AP33,"_","TR","_",Tab_4.DISP_INEX[[#This Row],[FORNECEDOR]]) -> 29_TR_Bioseg Brasília Soluções em Segurança e Medicina do Trabalho Ltda | AR33: =_xlfn.CONCAT(AP33,"_","JUST","_",Tab_4.DISP_INEX[[#This Row],[FORNECEDOR]]) -> 29_JUST_Bioseg Brasília Soluções em Segurança e Medicina do Trabalho Ltda | AS33: =_xlfn.CONCAT(AP33,"_","RAT","_",Tab_4.DISP_INEX[[#This Row],[FORNECEDOR]]) -> 29_RAT_Bioseg Brasília Soluções em Segurança e Medicina do Trabalho Ltda
B34: 45587 | C34: ROSILDA | D34: FINALIZADO | E34: FINALIZADO | F34: TLB-PRO-2024/05477 | G34: 2000-DAFRI | H34: GCC | I34: Serviços | J34: Contratação da ferramenta de pesquisa e comparação de preços praticados pela administração pública, denominada Banco de Preços | K34: Inexigibilidade | L34: ADMINISTRATIVO | M34: NP Tecnologia e Gestão de Dados Ltda | N34: 07.797.967/0001-95 | O34: Nota de Empenho | P34: 2024NE001046 | Q34: 2024NE001046 | R34: TLB-ASS-2024/15214 | S34: 45590 | T34: 45595 | U34: 45595 | V34: 11960 | W34: TLB-DEG-2024/00125 | X34: ROSILDA ABREU DA SILVA | Y34: PÚBLICO | Z34: 10014984 | AB34: 2024NE001046 | AC34: 45595 | AD34: =NETWORKDAYS.INTL(Tab_4.DISP_INEX[[#This Row],[DATA RECEBIDO]],Tab_4.DISP_INEX[[#This Row],[DATA FINALIZADO]],1,Lista!$U$3:$U$15) -> 7 | AE34: ROSILDA | AJ34: https://www.telebras.com.br/wp-content/uploads/2024/12/59.2024NE001046-NP-Tecnologia-e-Gestao-de-Dados-Ltda.pdf | AK34: https://www.telebras.com.br/wp-content/uploads/2026/06/30_TR_NP-Tecnologia-e-Gestao-de-Dados-Ltda.pdf | AL34: https://www.telebras.com.br/wp-content/uploads/2026/06/30_JUST_NP-Tecnologia-e-Gestao-de-Dados-Ltda.pdf | AM34: https://www.telebras.com.br/wp-content/uploads/2026/06/30_RAT_NP-Tecnologia-e-Gestao-de-Dados-Ltda.pdf | AP34: 30 | AQ34: =_xlfn.CONCAT(AP34,"_","TR","_",Tab_4.DISP_INEX[[#This Row],[FORNECEDOR]]) -> 30_TR_NP Tecnologia e Gestão de Dados Ltda | AR34: =_xlfn.CONCAT(AP34,"_","JUST","_",Tab_4.DISP_INEX[[#This Row],[FORNECEDOR]]) -> 30_JUST_NP Tecnologia e Gestão de Dados Ltda | AS34: =_xlfn.CONCAT(AP34,"_","RAT","_",Tab_4.DISP_INEX[[#This Row],[FORNECEDOR]]) -> 30_RAT_NP Tecnologia e Gestão de Dados Ltda
B35: 45610 | C35: ROSILDA | D35: FINALIZADO | E35: FINALIZADO | F35: TLB-PRO-2024/06064 | G35: 2000-DAFRI | H35: GGP | I35: Serviços | J35: Capacitação Credenciamento | K35: Inexigibilidade | L35: ADMINISTRATIVO | M35: Zênite Informação e Consultoria S/A | N35: 86.781.069/0001-15 | O35: Nota de Empenho | P35: 2024NE001078 | Q35: 2024NE001078 | R35: TLB-ASS-2024/16489 | S35: 45623 | T35: 45624 | U35: 45624 | V35: 3944 | W35: TLB-DEG-2024/00129 | X35: ROSILDA ABREU DA SILVA | Y35: PÚBLICO | Z35: 10015151 | AB35: 2024NE001078 | AC35: 45624 | AD35: =NETWORKDAYS.INTL(Tab_4.DISP_INEX[[#This Row],[DATA RECEBIDO]],Tab_4.DISP_INEX[[#This Row],[DATA FINALIZADO]],1,Lista!$U$3:$U$15) -> 9 | AE35: ROSILDA | AF35: CAPACITAÇÃO | AJ35: https://www.telebras.com.br/wp-content/uploads/2025/02/70.2024NE001078-ZENITE-INFORMACAO-E-CONSULTORIA-SA.pdf | AK35: https://www.telebras.com.br/wp-content/uploads/2026/06/31_TR_Zenite-Informacao-e-Consultoria-SA.pdf | AL35: https://www.telebras.com.br/wp-content/uploads/2026/06/31_JUST_Zenite-Informacao-e-Consultoria-SA.pdf | AM35: https://www.telebras.com.br/wp-content/uploads/2026/06/31_RAT_Zenite-Informacao-e-Consultoria-SA.pdf | AP35: 31 | AQ35: =_xlfn.CONCAT(AP35,"_","TR","_",Tab_4.DISP_INEX[[#This Row],[FORNECEDOR]]) -> 31_TR_Zênite Informação e Consultoria S/A | AR35: =_xlfn.CONCAT(AP35,"_","JUST","_",Tab_4.DISP_INEX[[#This Row],[FORNECEDOR]]) -> 31_JUST_Zênite Informação e Consultoria S/A | AS35: =_xlfn.CONCAT(AP35,"_","RAT","_",Tab_4.DISP_INEX[[#This Row],[FORNECEDOR]]) -> 31_RAT_Zênite Informação e Consultoria S/A
B36: 45618 | C36: FRANCIELE | D36: FINALIZADO | E36: FINALIZADO | F36: TLB-PRO-2024/06102 | G36: 2000-DAFRI | H36: GGP | I36: Serviços | J36: Curso Treinamento Executivo Risk University | K36: Inexigibilidade | L36: ADMINISTRATIVO | M36: KPMG Consultoria Ltda | N36: 01.708.167/0001-74 | O36: Nota de Empenho | P36: 2024NE001079 | Q36: 2024NE001079 | R36: TLB-ASS-2024/16552 | S36: 45628 | T36: 45628 | U36: 45628 | V36: 22066 | X36: ADRYANA RAMOS DE OLIVEIRA | Y36: PÚBLICO | Z36: 10015075 | AB36: 2024NE001079 | AC36: 45622 | AD36: =NETWORKDAYS.INTL(Tab_4.DISP_INEX[[#This Row],[DATA RECEBIDO]],Tab_4.DISP_INEX[[#This Row],[DATA FINALIZADO]],1,Lista!$U$3:$U$15) -> 3 | AE36: FRANCIELE | AF36: PROCESSO CANCELADO E INSTAURADO NOVO | AJ36: https://www.telebras.com.br/wp-content/uploads/2025/02/71.2024NE001081-INSTITUTO-BRASILEIRO-DE-GOVERNANCA-CORPORATIV_1.pdf | AK36: https://www.telebras.com.br/wp-content/uploads/2026/06/32_TR_KPMG-Consultoria-Ltda.pdf | AL36: https://www.telebras.com.br/wp-content/uploads/2026/06/32_JUST_KPMG-Consultoria-Ltda.pdf | AM36: https://www.telebras.com.br/wp-content/uploads/2026/06/32_RAT_KPMG-Consultoria-Ltda.pdf | AP36: 32 | AQ36: =_xlfn.CONCAT(AP36,"_","TR","_",Tab_4.DISP_INEX[[#This Row],[FORNECEDOR]]) -> 32_TR_KPMG Consultoria Ltda | AR36: =_xlfn.CONCAT(AP36,"_","JUST","_",Tab_4.DISP_INEX[[#This Row],[FORNECEDOR]]) -> 32_JUST_KPMG Consultoria Ltda | AS36: =_xlfn.CONCAT(AP36,"_","RAT","_",Tab_4.DISP_INEX[[#This Row],[FORNECEDOR]]) -> 32_RAT_KPMG Consultoria Ltda
B37: 45621 | C37: FRANCIELE | D37: FINALIZADO | E37: FINALIZADO | F37: TLB-PRO-2024/06203 | G37: 2000-DAFRI | H37: GGP | I37: Serviços | J37: Curso Governança Corporativa para Empresas Estatais | K37: Inexigibilidade | L37: ADMINISTRATIVO | M37: INSTITUTO BRASILEIRO DE GOVERNANÇA CORPORATIVA | N37: 01.082.331/0001-80 | O37: Nota de Empenho | P37: 2024NE001081 | Q37: 2024NE001081 | R37: TLB-ASS-2024/16583 | S37: 45625 | T37: 45629 | U37: 45629 | V37: 36800 | W37: TLB-DEG-2024/00130 | X37: ADRYANA RAMOS DE OLIVEIRA | Y37: PÚBLICO | Z37: 10015226 | AA37: 10003951 | AB37: 2024NE001081 | AC37: 45623 | AD37: =NETWORKDAYS.INTL(Tab_4.DISP_INEX[[#This Row],[DATA RECEBIDO]],Tab_4.DISP_INEX[[#This Row],[DATA FINALIZADO]],1,Lista!$U$3:$U$15) -> 3 | AE37: FRANCIELE | AF37: CAPACITAÇÃO | AJ37: https://www.telebras.com.br/wp-content/uploads/2025/02/71.2024NE001081-INSTITUTO-BRASILEIRO-DE-GOVERNANCA-CORPORATIV_1.pdf | AK37: https://www.telebras.com.br/wp-content/uploads/2026/06/33_TR_INSTITUTO-BRASILEIRO-DE-GOVERNANCA-CORPORATIVA.pdf | AL37: https://www.telebras.com.br/wp-content/uploads/2026/06/33_JUST_INSTITUTO-BRASILEIRO-DE-GOVERNANCA-CORPORATIVA.pdf | AM37: https://www.telebras.com.br/wp-content/uploads/2026/06/33_RAT_INSTITUTO-BRASILEIRO-DE-GOVERNANCA-CORPORATIVA.pdf | AP37: 33 | AQ37: =_xlfn.CONCAT(AP37,"_","TR","_",Tab_4.DISP_INEX[[#This Row],[FORNECEDOR]]) -> 33_TR_INSTITUTO BRASILEIRO DE GOVERNANÇA CORPORATIVA | AR37: =_xlfn.CONCAT(AP37,"_","JUST","_",Tab_4.DISP_INEX[[#This Row],[FORNECEDOR]]) -> 33_JUST_INSTITUTO BRASILEIRO DE GOVERNANÇA CORPORATIVA | AS37: =_xlfn.CONCAT(AP37,"_","RAT","_",Tab_4.DISP_INEX[[#This Row],[FORNECEDOR]]) -> 33_RAT_INSTITUTO BRASILEIRO DE GOVERNANÇA CORPORATIVA
B38: 45624 | C38: FRANCIELE | D38: FINALIZADO | E38: FINALIZADO | F38: TLB-PRO-2024/06226 | G38: 2000-DAFRI | H38: GGP | I38: Serviços | J38: Treinamento na Trilha: Tecnologia celular 4G – LTE | K38: Inexigibilidade | L38: ADMINISTRATIVO | M38: Fundação Instituto Nacional de Telecomunicações | N38: 24.492.886/0001-04 | O38: Nota de Empenho | P38: 2024NE001084 | Q38: 2024NE001084 | R38: TLB-ASS-2024/16671 | S38: 45628 | T38: 45630 | U38: 45630 | V38: 5397.3 | W38: TLB-DEG-2024/00134 | X38: ADRYANA RAMOS DE OLIVEIRA | Y38: PÚBLICO | Z38: 10015230 | AA38: 10004137 | AB38: 2024NE001084 | AC38: 45624 | AD38: =NETWORKDAYS.INTL(Tab_4.DISP_INEX[[#This Row],[DATA RECEBIDO]],Tab_4.DISP_INEX[[#This Row],[DATA FINALIZADO]],1,Lista!$U$3:$U$15) -> 1 | AE38: FRANCIELE | AF38: CAPACITAÇÃO | AJ38: https://www.telebras.com.br/wp-content/uploads/2025/02/72.2024NE001084-FUNDACAO-INSTITUTO-NACIONAL-DE-TELECOMUNICACO_2.pdf | AK38: https://www.telebras.com.br/wp-content/uploads/2026/06/34_TR_Fundacao-Instituto-Nacional-de-Telecomunicacoes.pdf | AL38: https://www.telebras.com.br/wp-content/uploads/2026/06/34_JUST_Fundacao-Instituto-Nacional-de-Telecomunicacoes.pdf | AM38: https://www.telebras.com.br/wp-content/uploads/2026/06/34_RAT_Fundacao-Instituto-Nacional-de-Telecomunicacoes.pdf | AP38: 34 | AQ38: =_xlfn.CONCAT(AP38,"_","TR","_",Tab_4.DISP_INEX[[#This Row],[FORNECEDOR]]) -> 34_TR_Fundação Instituto Nacional de Telecomunicações | AR38: =_xlfn.CONCAT(AP38,"_","JUST","_",Tab_4.DISP_INEX[[#This Row],[FORNECEDOR]]) -> 34_JUST_Fundação Instituto Nacional de Telecomunicações | AS38: =_xlfn.CONCAT(AP38,"_","RAT","_",Tab_4.DISP_INEX[[#This Row],[FORNECEDOR]]) -> 34_RAT_Fundação Instituto Nacional de Telecomunicações
B39: 45622 | C39: FRANCIELE | D39: FINALIZADO | E39: FINALIZADO | F39: TLB-PRO-2024/06217 | G39: 2000-DAFRI | H39: GGP | I39: Serviços | J39: Formação de Facilitadores em Modelagem da Cultura Organizacional | K39: Inexigibilidade | L39: ADMINISTRATIVO | M39: Akademia de Transformação Organizacional LTDA | N39: 29.484.585/0001-44 | O39: Nota de Empenho | P39: 2024NE001085 | Q39: 2024NE001085 | R39: TLB-ASS-2024/16672 | S39: 45628 | T39: 45630 | U39: 45630 | V39: 2497 | W39: TLB-DEG-2024/00135 | X39: MADALENE MENEZES VERTELO | Y39: PÚBLICO | Z39: 10015234 | AA39: 10004138 | AB39: 2024NE001085 | AC39: 45624 | AD39: =NETWORKDAYS.INTL(Tab_4.DISP_INEX[[#This Row],[DATA RECEBIDO]],Tab_4.DISP_INEX[[#This Row],[DATA FINALIZADO]],1,Lista!$U$3:$U$15) -> 3 | AE39: FRANCIELE | AF39: CAPACITAÇÃO | AJ39: https://www.telebras.com.br/wp-content/uploads/2025/02/73.2024NE001085-AKADEMIA-DE-TRANSFORMACAO-ORGANIZACIONAL-LTDA.pdf | AK39: https://www.telebras.com.br/wp-content/uploads/2026/06/35_TR_Akademia-de-Transformacao-Organizacional-LTDA.pdf | AL39: https://www.telebras.com.br/wp-content/uploads/2026/06/35_JUST_Akademia-de-Transformacao-Organizacional-LTDA.pdf | AM39: https://www.telebras.com.br/wp-content/uploads/2026/06/35_RAT_Akademia-de-Transformacao-Organizacional-LTDA.pdf | AP39: 35 | AQ39: =_xlfn.CONCAT(AP39,"_","TR","_",Tab_4.DISP_INEX[[#This Row],[FORNECEDOR]]) -> 35_TR_Akademia de Transformação Organizacional LTDA | AR39: =_xlfn.CONCAT(AP39,"_","JUST","_",Tab_4.DISP_INEX[[#This Row],[FORNECEDOR]]) -> 35_JUST_Akademia de Transformação Organizacional LTDA | AS39: =_xlfn.CONCAT(AP39,"_","RAT","_",Tab_4.DISP_INEX[[#This Row],[FORNECEDOR]]) -> 35_RAT_Akademia de Transformação Organizacional LTDA
B40: 45623 | C40: FRANCIELE | D40: FINALIZADO | E40: FINALIZADO | F40: TLB-PRO-2024/06221 | G40: 2000-DAFRI | H40: GGP | I40: Serviços | J40: Capacitação Técnica em Comunicação e Produção de Conteúdo para Gestão do Conhecimento. | K40: Inexigibilidade | L40: ADMINISTRATIVO | M40: Mariana Rodrigues de Lima | N40: 52.552.337/0001-05 | O40: Nota de Empenho | P40: 2024NE001082 | Q40: 2024NE001082 | R40: TLB-ASS-2024/16669 | S40: 02/12/2024 | T40: 45630 | U40: 45630 | V40: 8000 | W40: TLB-DEG-2024/00136 | X40: CAMILA DANIELA LIMA DE SOUZA GOMES | Y40: PÚBLICO | Z40: 10015238 | AA40: 10004139 | AB40: 2024NE001082 | AC40: 45624 | AD40: =NETWORKDAYS.INTL(Tab_4.DISP_INEX[[#This Row],[DATA RECEBIDO]],Tab_4.DISP_INEX[[#This Row],[DATA FINALIZADO]],1,Lista!$U$3:$U$15) -> 2 | AE40: FRANCIELE | AF40: CAPACITAÇÃO | AJ40: https://www.telebras.com.br/wp-content/uploads/2025/02/74.2024NE001082-MARIANA-RODRIGUES-DE-LIMA_3.pdf | AK40: - | AL40: - | AM40: - | AP40: 36 | AQ40: =_xlfn.CONCAT(AP40,"_","TR","_",Tab_4.DISP_INEX[[#This Row],[FORNECEDOR]]) -> 36_TR_Mariana Rodrigues de Lima | AR40: =_xlfn.CONCAT(AP40,"_","JUST","_",Tab_4.DISP_INEX[[#This Row],[FORNECEDOR]]) -> 36_JUST_Mariana Rodrigues de Lima | AS40: =_xlfn.CONCAT(AP40,"_","RAT","_",Tab_4.DISP_INEX[[#This Row],[FORNECEDOR]]) -> 36_RAT_Mariana Rodrigues de Lima
